Traceback (most recent call last):
  File "/home/phil/mini38/envs/work/lib/python3.8/site-packages/jupyter_cache/executors/utils.py", line 51, in single_nb_execution
    executenb(
  File "/home/phil/mini38/envs/work/lib/python3.8/site-packages/nbclient/client.py", line 1082, in execute
    return NotebookClient(nb=nb, resources=resources, km=km, **kwargs).execute()
  File "/home/phil/mini38/envs/work/lib/python3.8/site-packages/nbclient/util.py", line 74, in wrapped
    return just_run(coro(*args, **kwargs))
  File "/home/phil/mini38/envs/work/lib/python3.8/site-packages/nbclient/util.py", line 53, in just_run
    return loop.run_until_complete(coro)
  File "/home/phil/mini38/envs/work/lib/python3.8/asyncio/base_events.py", line 616, in run_until_complete
    return future.result()
  File "/home/phil/mini38/envs/work/lib/python3.8/site-packages/nbclient/client.py", line 535, in async_execute
    await self.async_execute_cell(
  File "/home/phil/mini38/envs/work/lib/python3.8/site-packages/nbclient/client.py", line 827, in async_execute_cell
    self._check_raise_for_error(cell, exec_reply)
  File "/home/phil/mini38/envs/work/lib/python3.8/site-packages/nbclient/client.py", line 735, in _check_raise_for_error
    raise CellExecutionError.from_cell_and_msg(cell, exec_reply['content'])
nbclient.exceptions.CellExecutionError: An error occurred while executing the following cell:
------------------
fig,theAx=plt.subplots(1,1)
[hydroPress=pressL[0]*np.exp(-zL/Hbar)
theAx.plot(pressL/100.,zL/1000.,label='sounding')
theAx.plot(hydroPress/100.,zL/1000.,label='hydrostat approx')
theAx.set_title('height vs. pressure for tropics')
theAx.set_xlabel('pressure (hPa)')
theAx.set_ylabel('height (km)')
theAx.set_xlim([500,1000])
theAx.set_ylim([0,5])
tickVals=[500, 600, 700, 800, 900, 1000]
theAx.set_xticks(tickVals)
theAx.set_xticklabels(tickVals)
theAx.legend(loc='best');
------------------

[0;36m  File [0;32m"<ipython-input-12-9c2a4f27396a>"[0;36m, line [0;32m2[0m
[0;31m    [hydroPress=pressL[0]*np.exp(-zL/Hbar)[0m
[0m               ^[0m
[0;31mSyntaxError[0m[0;31m:[0m invalid syntax

SyntaxError: invalid syntax (<ipython-input-12-9c2a4f27396a>, line 2)

