Traceback (most recent call last):
  File "/home/phil/mini38/envs/work/lib/python3.8/site-packages/jupyter_cache/executors/utils.py", line 51, in single_nb_execution
    executenb(
  File "/home/phil/mini38/envs/work/lib/python3.8/site-packages/nbclient/client.py", line 1082, in execute
    return NotebookClient(nb=nb, resources=resources, km=km, **kwargs).execute()
  File "/home/phil/mini38/envs/work/lib/python3.8/site-packages/nbclient/util.py", line 74, in wrapped
    return just_run(coro(*args, **kwargs))
  File "/home/phil/mini38/envs/work/lib/python3.8/site-packages/nbclient/util.py", line 53, in just_run
    return loop.run_until_complete(coro)
  File "/home/phil/mini38/envs/work/lib/python3.8/asyncio/base_events.py", line 616, in run_until_complete
    return future.result()
  File "/home/phil/mini38/envs/work/lib/python3.8/site-packages/nbclient/client.py", line 535, in async_execute
    await self.async_execute_cell(
  File "/home/phil/mini38/envs/work/lib/python3.8/site-packages/nbclient/client.py", line 827, in async_execute_cell
    self._check_raise_for_error(cell, exec_reply)
  File "/home/phil/mini38/envs/work/lib/python3.8/site-packages/nbclient/client.py", line 735, in _check_raise_for_error
    raise CellExecutionError.from_cell_and_msg(cell, exec_reply['content'])
nbclient.exceptions.CellExecutionError: An error occurred while executing the following cell:
------------------
m5_file= (a301_lib.sat_data / 'hdf4_files').glob("**/MYD05*2105*hdf")
m3_file = (a301_lib.sat_data / 'hdf4_files/myd03').glob("MYD03*2105*.hdf")
m5_file_str = str(list(m5_file)[0])
m3_file_str = str(list(m3_file)[0])
print(m5_file_str)
print(m3_file_str)

the_file = SD(m3_file_str, SDC.READ)
lats_1km = the_file.select("Latitude").get()
lons_1km = the_file.select("Longitude").get()
the_file.end()
print(lats_1km.shape)

the_file = SD(m5_file_str, SDC.READ)
lats_5km = the_file.select("Latitude").get()
lons_5km = the_file.select("Longitude").get()
the_file.end()
print(lats_5km.shape)
------------------

[0;31m---------------------------------------------------------------------------[0m
[0;31mIndexError[0m                                Traceback (most recent call last)
[0;32m<ipython-input-3-4355884dfdf5>[0m in [0;36m<module>[0;34m[0m
[1;32m      2[0m [0mm3_file[0m [0;34m=[0m [0;34m([0m[0ma301_lib[0m[0;34m.[0m[0msat_data[0m [0;34m/[0m [0;34m'hdf4_files/myd03'[0m[0;34m)[0m[0;34m.[0m[0mglob[0m[0;34m([0m[0;34m"MYD03*2105*.hdf"[0m[0;34m)[0m[0;34m[0m[0;34m[0m[0m
[1;32m      3[0m [0mm5_file_str[0m [0;34m=[0m [0mstr[0m[0;34m([0m[0mlist[0m[0;34m([0m[0mm5_file[0m[0;34m)[0m[0;34m[[0m[0;36m0[0m[0;34m][0m[0;34m)[0m[0;34m[0m[0;34m[0m[0m
[0;32m----> 4[0;31m [0mm3_file_str[0m [0;34m=[0m [0mstr[0m[0;34m([0m[0mlist[0m[0;34m([0m[0mm3_file[0m[0;34m)[0m[0;34m[[0m[0;36m0[0m[0;34m][0m[0;34m)[0m[0;34m[0m[0;34m[0m[0m
[0m[1;32m      5[0m [0mprint[0m[0;34m([0m[0mm5_file_str[0m[0;34m)[0m[0;34m[0m[0;34m[0m[0m
[1;32m      6[0m [0mprint[0m[0;34m([0m[0mm3_file_str[0m[0;34m)[0m[0;34m[0m[0;34m[0m[0m

[0;31mIndexError[0m: list index out of range
IndexError: list index out of range

