Traceback (most recent call last):
  File "/home/phil/mini38/envs/work/lib/python3.8/site-packages/jupyter_cache/executors/utils.py", line 51, in single_nb_execution
    executenb(
  File "/home/phil/mini38/envs/work/lib/python3.8/site-packages/nbclient/client.py", line 1082, in execute
    return NotebookClient(nb=nb, resources=resources, km=km, **kwargs).execute()
  File "/home/phil/mini38/envs/work/lib/python3.8/site-packages/nbclient/util.py", line 74, in wrapped
    return just_run(coro(*args, **kwargs))
  File "/home/phil/mini38/envs/work/lib/python3.8/site-packages/nbclient/util.py", line 53, in just_run
    return loop.run_until_complete(coro)
  File "/home/phil/mini38/envs/work/lib/python3.8/asyncio/base_events.py", line 616, in run_until_complete
    return future.result()
  File "/home/phil/mini38/envs/work/lib/python3.8/site-packages/nbclient/client.py", line 535, in async_execute
    await self.async_execute_cell(
  File "/home/phil/mini38/envs/work/lib/python3.8/site-packages/nbclient/client.py", line 827, in async_execute_cell
    self._check_raise_for_error(cell, exec_reply)
  File "/home/phil/mini38/envs/work/lib/python3.8/site-packages/nbclient/client.py", line 735, in _check_raise_for_error
    raise CellExecutionError.from_cell_and_msg(cell, exec_reply['content'])
nbclient.exceptions.CellExecutionError: An error occurred while executing the following cell:
------------------
swath_info = parseMeta(core_metadata)
proj_params = get_proj_params(swath_info)
proj_params['lon_0'] = lon_0
proj_params['lat_0'] = lat_0
#breakpoint()
------------------

[0;31m---------------------------------------------------------------------------[0m
[0;31mUnboundLocalError[0m                         Traceback (most recent call last)
[0;32m<ipython-input-4-b2ed01de8d39>[0m in [0;36m<module>[0;34m[0m
[1;32m      1[0m [0mswath_info[0m [0;34m=[0m [0mparseMeta[0m[0;34m([0m[0mcore_metadata[0m[0;34m)[0m[0;34m[0m[0;34m[0m[0m
[0;32m----> 2[0;31m [0mproj_params[0m [0;34m=[0m [0mget_proj_params[0m[0;34m([0m[0mswath_info[0m[0;34m)[0m[0;34m[0m[0;34m[0m[0m
[0m[1;32m      3[0m [0mproj_params[0m[0;34m[[0m[0;34m'lon_0'[0m[0;34m][0m [0;34m=[0m [0mlon_0[0m[0;34m[0m[0;34m[0m[0m
[1;32m      4[0m [0mproj_params[0m[0;34m[[0m[0;34m'lat_0'[0m[0;34m][0m [0;34m=[0m [0mlat_0[0m[0;34m[0m[0;34m[0m[0m
[1;32m      5[0m [0;31m#breakpoint()[0m[0;34m[0m[0;34m[0m[0;34m[0m[0m

[0;32m~/work/sat_lib/geometry.py[0m in [0;36mget_proj_params[0;34m(input_swath)[0m
[1;32m     39[0m     [0;32mimport[0m [0mcartopy[0m[0;34m.[0m[0mcrs[0m [0;32mas[0m [0mccrs[0m[0;34m[0m[0;34m[0m[0m
[1;32m     40[0m     [0mglobe_w[0m [0;34m=[0m [0mccrs[0m[0;34m.[0m[0mGlobe[0m[0;34m([0m[0mdatum[0m[0;34m=[0m[0;34m"WGS84"[0m[0;34m,[0m[0mellipse[0m[0;34m=[0m[0;34m"WGS84"[0m[0;34m)[0m[0;34m[0m[0;34m[0m[0m
[0;32m---> 41[0;31m     projection_w=ccrs.LambertAzimuthalEqualArea(central_latitude=modis_dict['lat_0'],
[0m[1;32m     42[0m                     central_longitude= modis_dict['lon_0'],globe=globe_w)
[1;32m     43[0m     [0mproj_params[0m[0;34m=[0m[0mprojection_w[0m[0;34m.[0m[0mproj4_params[0m[0;34m[0m[0;34m[0m[0m

[0;31mUnboundLocalError[0m: local variable 'modis_dict' referenced before assignment
UnboundLocalError: local variable 'modis_dict' referenced before assignment

